
pip3 install celery
pip3 install redis
pip3 install django-celery-results
pip3 install django-celery-beat
pip3 install eventlet


https://blog.csdn.net/libing_thinking/article/details/78622943   Celery3 迁移到 celery4 遇到的问题
https://www.cnblogs.com/zh605929205/p/9861058.html    Celery-4.1 用户指南: Task(任务)



linux :

shell> celery
-bash: celery: command not found
	ln -s /usr/local/python3/bin/celery /usr/bin/celery

	
shell> pwd
/root/python/terrace/automatic

	shell> celery  -A automatic worker -l info -P eventlet

	
shell> celery  -A automatic worker -l info -P eventlet
	(0.000) SELECT @@SQL_AUTO_IS_NULL; args=None
	(0.000) SET SESSION TRANSACTION ISOLATION LEVEL READ COMMITTED; args=None
	(0.000) SELECT VERSION(); args=None
	/usr/local/python3/lib/python3.6/site-packages/celery/platforms.py:801: RuntimeWarning: You're running the worker with superuser privileges: this is
	absolutely not recommended!

	Please specify a different user using the --uid option.

	User information: uid=0 euid=0 gid=0 egid=0

	  uid=uid, euid=euid, gid=gid, egid=egid,
	 
	 -------------- celery@mgr9 v4.3.0 (rhubarb)
	---- **** ----- 
	--- * ***  * -- Linux-3.10.0-693.el7.x86_64-x86_64-with-centos-7.4.1708-Core 2019-10-17 22:24:37
	-- * - **** --- 
	- ** ---------- [config]
	- ** ---------- .> app:         automatic:0x7f6a8dbf7780
	- ** ---------- .> transport:   redis://127.0.0.1:6379/2
	- ** ---------- .> results:     redis://127.0.0.1:6379/3
	- *** --- * --- .> concurrency: 1 (eventlet)
	-- ******* ---- .> task events: OFF (enable -E to monitor tasks in this worker)
	--- ***** ----- 
	 -------------- [queues]
					.> celery           exchange=celery(direct) key=celery
					

	[tasks]


	[2019-10-17 22:24:37,068: INFO/MainProcess] Connected to redis://127.0.0.1:6379/2
	[2019-10-17 22:24:37,074: INFO/MainProcess] mingle: searching for neighbors
	[2019-10-17 22:24:38,097: INFO/MainProcess] mingle: all alone
	[2019-10-17 22:24:38,128: INFO/MainProcess] pidbox: Connected to redis://127.0.0.1:6379/2.
	[2019-10-17 22:24:38,135: WARNING/MainProcess] /usr/local/python3/lib/python3.6/site-packages/celery/fixups/django.py:202: UserWarning: Using settings.DEBUG leads to a memory leak, never use this setting in production environments!
	  warnings.warn('Using settings.DEBUG leads to a memory leak, never '
	[2019-10-17 22:24:38,135: INFO/MainProcess] celery@mgr9 ready.



windows: 
# 启动 Celery
	E:\20180411\project\python\python_note\Django\MyDjango>celery -A MyDjango worker -l info -P eventlet
	(0.000) SELECT @@SQL_AUTO_IS_NULL; args=None
	(0.000) SET SESSION TRANSACTION ISOLATION LEVEL READ COMMITTED; args=None
	(0.001) SELECT VERSION(); args=None

	 -------------- celery@DELL-PC-056 v4.3.0 (rhubarb)
	---- **** -----
	--- * ***  * -- Windows-7-6.1.7601-SP1 2019-10-21 15:30:41
	-- * - **** ---
	- ** ---------- [config]
	- ** ---------- .> app:         MyDjango:0x376f550
	- ** ---------- .> transport:   redis://127.0.0.1:6379/0
	- ** ---------- .> results:     redis://127.0.0.1:6379/1
	- *** --- * --- .> concurrency: 4 (eventlet)
	-- ******* ---- .> task events: OFF (enable -E to monitor tasks in this worker)
	--- ***** -----
	 -------------- [queues]
					.> celery           exchange=celery(direct) key=celery


	[tasks]
	  . MyDjango.celery.debug_task
	  . index.tasks.updateData

	[2019-10-21 15:30:41,463: INFO/MainProcess] Connected to redis://127.0.0.1:6379/0
	[2019-10-21 15:30:41,471: INFO/MainProcess] mingle: searching for neighbors
	[2019-10-21 15:30:42,519: INFO/MainProcess] mingle: all alone
	[2019-10-21 15:30:42,540: WARNING/MainProcess] d:\python\lib\site-packages\celery\fixups\django.py:202: UserWarning: Using settings.DEBUG leads to a memory leak, never use this setting in production environments!
	  warnings.warn('Using settings.DEBUG leads to a memory leak, never '
	[2019-10-21 15:30:42,541: INFO/MainProcess] celery@DELL-PC-056 ready.
	[2019-10-21 15:30:42,556: INFO/MainProcess] pidbox: Connected to redis://127.0.0.1:6379/0.



# 执行异步任务:

	[2019-10-21 15:34:55,304: INFO/MainProcess] Received task: index.tasks.updateData[feec1863-c2e4-4494-80d3-815e59798022]
	(0.000) SELECT @@SQL_AUTO_IS_NULL; args=None
	[2019-10-21 15:34:55,312: DEBUG/MainProcess] (0.000) SELECT @@SQL_AUTO_IS_NULL; args=None
	(0.002) SET SESSION TRANSACTION ISOLATION LEVEL READ COMMITTED; args=None
	[2019-10-21 15:34:55,315: DEBUG/MainProcess] (0.002) SET SESSION TRANSACTION ISOLATION LEVEL READ COMMITTED; args=None
	(0.000) SELECT VERSION(); args=None
	[2019-10-21 15:34:55,319: DEBUG/MainProcess] (0.000) SELECT VERSION(); args=None
	(0.001) UPDATE `index_type` SET `type_name` = '任务测试_update1514' WHERE `index_type`.`id` = 3; args=('任务测试_update1514', 3)                                                                                                                                                                                     
	[2019-10-21 15:34:55,321: DEBUG/MainProcess] (0.001) UPDATE `index_type` SET `type_name` = '任务测试_update1514' WHERE `index_type`.`id` = 3; args=('任务测试_update1514', 3)                                                                                                                                        
	[2019-10-21 15:34:55,327: INFO/MainProcess] Task index.tasks.updateData[feec1863-c2e4-4494-80d3-815e59798022] succeeded in 0.016000000294297934s: None




E:\20180411\project\python\python_note\Django\MyDjango\MyDjango>celery -A MyDjango worker -1 info -P eventlet
Traceback (most recent call last):
  File "d:\python\lib\runpy.py", line 193, in _run_module_as_main
    "__main__", mod_spec)
  File "d:\python\lib\runpy.py", line 85, in _run_code
    exec(code, run_globals)
  File "D:\python\Scripts\celery.exe\__main__.py", line 9, in <module>
  File "d:\python\lib\site-packages\celery\__main__.py", line 14, in main
    maybe_patch_concurrency()
  File "d:\python\lib\site-packages\celery\__init__.py", line 145, in maybe_patch_concurrency
    patcher()
  File "d:\python\lib\site-packages\celery\__init__.py", line 100, in _patch_eventlet
    import eventlet
ModuleNotFoundError: No module named 'eventlet'


pip3 install eventlet

pip3 --default-timeout=100 install eventlet

E:\20180411\project\python\python_note\Django\MyDjango>pip3 install eventlet
Collecting eventlet
  Downloading https://files.pythonhosted.org/packages/ef/01/83454d11bac9015f34e9
3cf11efcae169390ddf2df97cb73ca86de6465ed/eventlet-0.25.1-py2.py3-none-any.whl (2
22kB)
ERROR: Exception:
Traceback (most recent call last):
  File "d:\python\lib\site-packages\pip-19.1.1-py3.6.egg\pip\_vendor\urllib3\res
ponse.py", line 360, in _error_catcher
    yield
  File "d:\python\lib\site-packages\pip-19.1.1-py3.6.egg\pip\_vendor\urllib3\res
ponse.py", line 442, in read
    data = self._fp.read(amt)
  File "d:\python\lib\site-packages\pip-19.1.1-py3.6.egg\pip\_vendor\cachecontro
l\filewrapper.py", line 62, in read
    data = self.__fp.read(amt)
  File "D:\python\lib\http\client.py", line 449, in read
    n = self.readinto(b)
  File "D:\python\lib\http\client.py", line 493, in readinto
    n = self.fp.readinto(b)
  File "D:\python\lib\socket.py", line 586, in readinto
    return self._sock.recv_into(b)
  File "D:\python\lib\ssl.py", line 1002, in recv_into
    return self.read(nbytes, buffer)
  File "D:\python\lib\ssl.py", line 865, in read
    return self._sslobj.read(len, buffer)
  File "D:\python\lib\ssl.py", line 625, in read
    v = self._sslobj.read(len, buffer)
socket.timeout: The read operation timed out

During handling of the above exception, another exception occurred:

Traceback (most recent call last):
  File "d:\python\lib\site-packages\pip-19.1.1-py3.6.egg\pip\_internal\cli\base_
command.py", line 178, in main
    status = self.run(options, args)
  File "d:\python\lib\site-packages\pip-19.1.1-py3.6.egg\pip\_internal\commands\
install.py", line 352, in run
    resolver.resolve(requirement_set)
  File "d:\python\lib\site-packages\pip-19.1.1-py3.6.egg\pip\_internal\resolve.p
y", line 131, in resolve
    self._resolve_one(requirement_set, req)
  File "d:\python\lib\site-packages\pip-19.1.1-py3.6.egg\pip\_internal\resolve.p
y", line 294, in _resolve_one
    abstract_dist = self._get_abstract_dist_for(req_to_install)
  File "d:\python\lib\site-packages\pip-19.1.1-py3.6.egg\pip\_internal\resolve.p
y", line 242, in _get_abstract_dist_for
    self.require_hashes
  File "d:\python\lib\site-packages\pip-19.1.1-py3.6.egg\pip\_internal\operation
s\prepare.py", line 347, in prepare_linked_requirement
    progress_bar=self.progress_bar
  File "d:\python\lib\site-packages\pip-19.1.1-py3.6.egg\pip\_internal\download.
py", line 886, in unpack_url
    progress_bar=progress_bar
  File "d:\python\lib\site-packages\pip-19.1.1-py3.6.egg\pip\_internal\download.
py", line 746, in unpack_http_url
    progress_bar)
  File "d:\python\lib\site-packages\pip-19.1.1-py3.6.egg\pip\_internal\download.
py", line 954, in _download_http_url
    _download_url(resp, link, content_file, hashes, progress_bar)
  File "d:\python\lib\site-packages\pip-19.1.1-py3.6.egg\pip\_internal\download.
py", line 683, in _download_url
    hashes.check_against_chunks(downloaded_chunks)
  File "d:\python\lib\site-packages\pip-19.1.1-py3.6.egg\pip\_internal\utils\has
hes.py", line 62, in check_against_chunks
    for chunk in chunks:
  File "d:\python\lib\site-packages\pip-19.1.1-py3.6.egg\pip\_internal\download.
py", line 651, in written_chunks
    for chunk in chunks:
  File "d:\python\lib\site-packages\pip-19.1.1-py3.6.egg\pip\_internal\utils\ui.
py", line 156, in iter
    for x in it:
  File "d:\python\lib\site-packages\pip-19.1.1-py3.6.egg\pip\_internal\download.
py", line 640, in resp_read
    decode_content=False):
  File "d:\python\lib\site-packages\pip-19.1.1-py3.6.egg\pip\_vendor\urllib3\res
ponse.py", line 494, in stream
    data = self.read(amt=amt, decode_content=decode_content)
  File "d:\python\lib\site-packages\pip-19.1.1-py3.6.egg\pip\_vendor\urllib3\res
ponse.py", line 459, in read
    raise IncompleteRead(self._fp_bytes_read, self.length_remaining)
  File "D:\python\lib\contextlib.py", line 100, in __exit__
    self.gen.throw(type, value, traceback)
  File "d:\python\lib\site-packages\pip-19.1.1-py3.6.egg\pip\_vendor\urllib3\res
ponse.py", line 365, in _error_catcher
    raise ReadTimeoutError(self._pool, None, 'Read timed out.')
pip._vendor.urllib3.exceptions.ReadTimeoutError: HTTPSConnectionPool(host='files
.pythonhosted.org', port=443): Read timed out.




