logger_test 2022-02-21 22:50:17 2022-02-21_mysql_fetchone.py:69 INFO this is a debug message
logger_test 2022-02-26 22:12:32 2022-02-21_mysql_fetchone.py:85 INFO this is a debug message
logger_test 2022-02-26 22:13:00 2022-02-21_mysql_fetchone.py:85 INFO this is a debug message
logger_test 2022-02-26 22:17:28 2022-02-26_mysql_fetchall.py:85 INFO this is a debug message
logger_test 2022-02-26 22:18:30 2022-02-26_mysql_fetchall.py:85 INFO this is a debug message
logger_test 2022-02-26 22:22:27 2022-02-21_mysql_fetchone.py:86 INFO this is a debug message
logger_test 2022-02-26 22:23:17 2022-02-21_mysql_fetchone.py:93 INFO this is a debug message
logger_test 2022-02-26 22:37:30 2022-02-21_mysql_fetchone.py:129 INFO this is a debug message
logger_test 2022-02-26 22:43:25 2022-02-21_mysql_fetchone.py:135 INFO this is a debug message
logger_test 2022-02-26 22:45:20 2022-02-21_mysql_fetchone.py:136 INFO this is a debug message
logger_test 2022-02-26 22:47:41 2022-02-21_mysql_fetchone.py:144 INFO this is a debug message
logger_test 2022-02-26 23:01:05 2022-02-21_mysql_fetchone.py:142 ERROR 'int' object is not callable
Traceback (most recent call last):
  File "d:\mysqlbin\git_project\python_note\2022-02-21- 数据库连接操作\2022-02-21_mysql_fetchone.py", line 87, in <module>
    print("rowcount: {}".format(cur.rowcount()))
TypeError: 'int' object is not callable
logger_test 2022-02-26 23:01:05 2022-02-21_mysql_fetchone.py:149 INFO this is a debug message
logger_test 2022-02-26 23:01:55 2022-02-21_mysql_fetchone.py:143 ERROR 'int' object is not callable
Traceback (most recent call last):
  File "d:\mysqlbin\git_project\python_note\2022-02-21- 数据库连接操作\2022-02-21_mysql_fetchone.py", line 87, in <module>
    print("rowcount: {}".format(cur.rowcount()))
TypeError: 'int' object is not callable
logger_test 2022-02-26 23:01:55 2022-02-21_mysql_fetchone.py:150 INFO this is a debug message
logger_test 2022-02-26 23:02:08 2022-02-21_mysql_fetchone.py:150 INFO this is a debug message
logger_test 2022-02-26 23:02:20 2022-02-21_mysql_fetchone.py:142 ERROR 'int' object is not callable
Traceback (most recent call last):
  File "d:\mysqlbin\git_project\python_note\2022-02-21- 数据库连接操作\2022-02-21_mysql_fetchone.py", line 89, in <module>
    print("rowcount: {}".format(cur.rowcount()))
TypeError: 'int' object is not callable
logger_test 2022-02-26 23:02:20 2022-02-21_mysql_fetchone.py:149 INFO this is a debug message
logger_test 2022-02-26 23:02:40 2022-02-21_mysql_fetchone.py:149 INFO this is a debug message
logger_test 2022-02-26 23:02:57 2022-02-21_mysql_fetchone.py:151 INFO this is a debug message
logger_test 2022-02-26 23:04:20 2022-02-21_mysql_fetchone.py:152 INFO this is a debug message
logger_test 2022-02-26 23:05:02 2022-02-21_mysql_fetchone.py:153 INFO this is a debug message
logger_test 2022-02-26 23:05:24 2022-02-26_mysql_fetchall.py:85 INFO this is a debug message
logger_test 2022-02-26 23:06:02 2022-02-26_mysql_fetchall.py:87 INFO this is a debug message
logger_test 2022-02-26 23:06:25 2022-02-26_mysql_fetchall.py:88 INFO this is a debug message
logger_test 2022-02-26 23:06:43 2022-02-21_mysql_fetchone.py:153 INFO this is a debug message
logger_test 2022-02-26 23:08:16 2022-02-26_mysql_fetchall.py:91 INFO this is a debug message
logger_test 2022-02-26 23:08:30 2022-02-26_mysql_fetchall.py:92 INFO this is a debug message
logger_test 2022-02-26 23:08:37 2022-02-26_mysql_fetchall.py:92 INFO this is a debug message
logger_test 2022-02-26 23:08:55 2022-02-26_mysql_fetchall.py:93 INFO this is a debug message
logger_test 2022-02-26 23:08:59 2022-02-26_mysql_fetchall.py:93 INFO this is a debug message
logger_test 2022-02-27 00:15:21 2022-02-21_mysql_fetchone.py:148 ERROR (1064, "You have an error in your SQL syntax; check the manual that corresponds to your MySQL server version for the right syntax to use near 'commit ',') from trade_detail where tradeid='aaaaaaad'' at line 1")
Traceback (most recent call last):
  File "d:\mysqlbin\git_project\python_note\2022-02-21- 数据库连接操作\2022-02-21_mysql_fetchone.py", line 85, in <module>
    cur.execute(sql)
  File "D:\mysqlbin\git_project\python_note\venv\lib\site-packages\pymysql\cursors.py", line 148, in execute
    result = self._query(query)
  File "D:\mysqlbin\git_project\python_note\venv\lib\site-packages\pymysql\cursors.py", line 310, in _query
    conn.query(q)
  File "D:\mysqlbin\git_project\python_note\venv\lib\site-packages\pymysql\connections.py", line 548, in query
    self._affected_rows = self._read_query_result(unbuffered=unbuffered)
  File "D:\mysqlbin\git_project\python_note\venv\lib\site-packages\pymysql\connections.py", line 775, in _read_query_result
    result.read()
  File "D:\mysqlbin\git_project\python_note\venv\lib\site-packages\pymysql\connections.py", line 1156, in read
    first_packet = self.connection._read_packet()
  File "D:\mysqlbin\git_project\python_note\venv\lib\site-packages\pymysql\connections.py", line 725, in _read_packet
    packet.raise_for_error()
  File "D:\mysqlbin\git_project\python_note\venv\lib\site-packages\pymysql\protocol.py", line 221, in raise_for_error
    err.raise_mysql_exception(self._data)
  File "D:\mysqlbin\git_project\python_note\venv\lib\site-packages\pymysql\err.py", line 143, in raise_mysql_exception
    raise errorclass(errno, errval)
pymysql.err.ProgrammingError: (1064, "You have an error in your SQL syntax; check the manual that corresponds to your MySQL server version for the right syntax to use near 'commit ',') from trade_detail where tradeid='aaaaaaad'' at line 1")
logger_test 2022-02-27 00:15:21 2022-02-21_mysql_fetchone.py:155 INFO this is a debug message
logger_test 2022-02-27 00:15:25 2022-02-21_mysql_fetchone.py:148 ERROR (1064, "You have an error in your SQL syntax; check the manual that corresponds to your MySQL server version for the right syntax to use near 'commit ',') from trade_detail where tradeid='aaaaaaad'' at line 1")
Traceback (most recent call last):
  File "d:\mysqlbin\git_project\python_note\2022-02-21- 数据库连接操作\2022-02-21_mysql_fetchone.py", line 85, in <module>
    cur.execute(sql)
  File "D:\mysqlbin\git_project\python_note\venv\lib\site-packages\pymysql\cursors.py", line 148, in execute
    result = self._query(query)
  File "D:\mysqlbin\git_project\python_note\venv\lib\site-packages\pymysql\cursors.py", line 310, in _query
    conn.query(q)
  File "D:\mysqlbin\git_project\python_note\venv\lib\site-packages\pymysql\connections.py", line 548, in query
    self._affected_rows = self._read_query_result(unbuffered=unbuffered)
  File "D:\mysqlbin\git_project\python_note\venv\lib\site-packages\pymysql\connections.py", line 775, in _read_query_result
    result.read()
  File "D:\mysqlbin\git_project\python_note\venv\lib\site-packages\pymysql\connections.py", line 1156, in read
    first_packet = self.connection._read_packet()
  File "D:\mysqlbin\git_project\python_note\venv\lib\site-packages\pymysql\connections.py", line 725, in _read_packet
    packet.raise_for_error()
  File "D:\mysqlbin\git_project\python_note\venv\lib\site-packages\pymysql\protocol.py", line 221, in raise_for_error
    err.raise_mysql_exception(self._data)
  File "D:\mysqlbin\git_project\python_note\venv\lib\site-packages\pymysql\err.py", line 143, in raise_mysql_exception
    raise errorclass(errno, errval)
pymysql.err.ProgrammingError: (1064, "You have an error in your SQL syntax; check the manual that corresponds to your MySQL server version for the right syntax to use near 'commit ',') from trade_detail where tradeid='aaaaaaad'' at line 1")
logger_test 2022-02-27 00:15:25 2022-02-21_mysql_fetchone.py:155 INFO this is a debug message
logger_test 2022-02-27 00:15:34 2022-02-21_mysql_fetchone.py:148 ERROR (1064, "You have an error in your SQL syntax; check the manual that corresponds to your MySQL server version for the right syntax to use near 'commit ',') from trade_detail where tradeid='aaaaaaad'' at line 1")
Traceback (most recent call last):
  File "d:\mysqlbin\git_project\python_note\2022-02-21- 数据库连接操作\2022-02-21_mysql_fetchone.py", line 85, in <module>
    cur.execute(sql)
  File "D:\mysqlbin\git_project\python_note\venv\lib\site-packages\pymysql\cursors.py", line 148, in execute
    result = self._query(query)
  File "D:\mysqlbin\git_project\python_note\venv\lib\site-packages\pymysql\cursors.py", line 310, in _query
    conn.query(q)
  File "D:\mysqlbin\git_project\python_note\venv\lib\site-packages\pymysql\connections.py", line 548, in query
    self._affected_rows = self._read_query_result(unbuffered=unbuffered)
  File "D:\mysqlbin\git_project\python_note\venv\lib\site-packages\pymysql\connections.py", line 775, in _read_query_result
    result.read()
  File "D:\mysqlbin\git_project\python_note\venv\lib\site-packages\pymysql\connections.py", line 1156, in read
    first_packet = self.connection._read_packet()
  File "D:\mysqlbin\git_project\python_note\venv\lib\site-packages\pymysql\connections.py", line 725, in _read_packet
    packet.raise_for_error()
  File "D:\mysqlbin\git_project\python_note\venv\lib\site-packages\pymysql\protocol.py", line 221, in raise_for_error
    err.raise_mysql_exception(self._data)
  File "D:\mysqlbin\git_project\python_note\venv\lib\site-packages\pymysql\err.py", line 143, in raise_mysql_exception
    raise errorclass(errno, errval)
pymysql.err.ProgrammingError: (1064, "You have an error in your SQL syntax; check the manual that corresponds to your MySQL server version for the right syntax to use near 'commit ',') from trade_detail where tradeid='aaaaaaad'' at line 1")
logger_test 2022-02-27 00:15:34 2022-02-21_mysql_fetchone.py:155 INFO this is a debug message
logger_test 2022-02-27 00:16:22 2022-02-21_mysql_fetchone.py:155 INFO this is a debug message
logger_test 2022-02-27 00:16:55 2022-02-21_mysql_fetchone.py:158 INFO this is a debug message
logger_test 2022-02-27 11:11:34 2022-02-21_mysql_fetchone.py:164 INFO this is a debug message
logger_test 2022-02-27 11:13:37 2022-02-26_mysql_fetchall.py:125 INFO this is a debug message
logger_test 2022-02-27 11:15:09 2022-02-26_mysql_fetchall.py:116 ERROR 'str' object has no attribute 'type'
Traceback (most recent call last):
  File "d:\mysqlbin\git_project\python_note\2022-02-21- 数据库连接操作\2022-02-26_mysql_fetchall.py", line 91, in <module>
    print("type(data): {}".type(data))
AttributeError: 'str' object has no attribute 'type'
logger_test 2022-02-27 11:15:09 2022-02-26_mysql_fetchall.py:123 INFO this is a debug message
logger_test 2022-02-27 11:15:30 2022-02-26_mysql_fetchall.py:117 ERROR 'str' object has no attribute 'type'
Traceback (most recent call last):
  File "d:\mysqlbin\git_project\python_note\2022-02-21- 数据库连接操作\2022-02-26_mysql_fetchall.py", line 91, in <module>
    print("type(data): {}".type(data))
AttributeError: 'str' object has no attribute 'type'
logger_test 2022-02-27 11:15:30 2022-02-26_mysql_fetchall.py:124 INFO this is a debug message
logger_test 2022-02-27 11:15:39 2022-02-26_mysql_fetchall.py:124 INFO this is a debug message
logger_test 2022-02-27 11:16:01 2022-02-26_mysql_fetchall.py:124 INFO this is a debug message
logger_test 2022-02-27 11:16:35 2022-02-26_mysql_fetchall.py:124 INFO this is a debug message
logger_test 2022-02-27 11:17:11 2022-02-26_mysql_fetchall.py:136 INFO this is a debug message
logger_test 2022-02-27 11:17:57 2022-02-26_mysql_fetchall.py:137 INFO this is a debug message
logger_test 2022-02-27 11:18:14 2022-02-26_mysql_fetchall.py:130 ERROR 'str' object has no attribute 'type'
Traceback (most recent call last):
  File "d:\mysqlbin\git_project\python_note\2022-02-21- 数据库连接操作\2022-02-26_mysql_fetchall.py", line 91, in <module>
    print("type(data): {}".type(data))
AttributeError: 'str' object has no attribute 'type'
logger_test 2022-02-27 11:18:14 2022-02-26_mysql_fetchall.py:137 INFO this is a debug message
logger_test 2022-02-27 11:18:26 2022-02-26_mysql_fetchall.py:137 INFO this is a debug message
logger_test 2022-02-27 11:19:29 2022-02-21_mysql_fetchone.py:176 INFO this is a debug message
logger_test 2022-02-27 11:21:54 2022-02-26_mysql_fetchall.py:150 INFO this is a debug message
logger_test 2022-02-27 11:21:57 2022-02-26_mysql_fetchall.py:150 INFO this is a debug message
